Workbook

Sheet RawData
A1: Model | B1: AQ7 URL | C1: AQ7 MS | D1: AQ7 Labor | E1: AQ7 Margin | F1: XO7 URL | G1: XO7 MS | H1: XO7 Labor | I1: XO7 Margin | J1: OEM Screen | K1: AM Battery | L1: OEM Battery | M1: Charge Port | N1: Back Glass | O1: Second Repair | P1: Third Repair
A2: iPhone 17 Pro Max | B2: https://www.mobilesentrix.ca/lcd-assembly-for-iphone-17-pro-max-aftermarket-aq7-incell-120hz | C2: 77.73 | D2: 100 | E2: =IFERROR((#REF! - C2) /#REF!, "") | F2: https://www.mobilesentrix.ca/oled-assembly-compatible-for-iphone-17-pro-max-aftermarket-pro-xo7-soft-120hz | G2: 204.73 | H2: 160 | I2: =IFERROR((#REF! - G2) /#REF!, "") | J2: 659 | K2: NA | L2: 179 | M2: 199 | N2: 149 | O2: 50% Off | P2: 70% off
A3: iPhone 17 Pro | B3: https://www.mobilesentrix.ca/lcd-assembly-for-iphone-17-pro-aftermarket-aq7-incell-120hz | C3: 77.73 | D3: 100 | E3: =IFERROR((#REF! - C3) /#REF!, "") | F3: https://www.mobilesentrix.ca/oled-assembly-compatible-for-iphone-17-pro-aftermarket-pro-xo7-soft-120hz | G3: 153.76 | H3: 160 | I3: =IFERROR((#REF! - G3) /#REF!, "") | J3: 579 | K3: NA | L3: 179 | M3: 199 | N3: 149 | O3: 50% Off | P3: 70% off
A4: iPhone 17 | B4: https://www.mobilesentrix.ca/lcd-assembly-for-iphone-17-aftermarket-aq7-incell-120hz | C4: 77.73 | D4: 100 | E4: =IFERROR((#REF! - C4) /#REF!, "") | F4: https://www.mobilesentrix.ca/oled-assembly-compatible-for-iphone-17-aftermarket-pro-xo7-soft-120hz | G4: 150.64 | H4: 150 | I4: =IFERROR((#REF! - G4) /#REF!, "") | J4: 559 | K4: NA | L4: 179 | M4: 199 | N4: 149 | O4: 50% Off | P4: 70% off
A5: Iphone Air | B5: Not Available | D5: 110 | E5: =IFERROR((#REF! - C5) /#REF!, "") | F5: https://www.mobilesentrix.ca/oled-assembly-compatible-for-iphone-air-aftermarket-pro-xo7-soft-120hz | G5: 293.94 | H5: 150 | I5: =IFERROR((#REF! - G5) /#REF!, "") | J5: 569 | K5: NA | L5: 179 | M5: 199 | N5: NA | O5: 50% Off | P5: 70% off
A6: iPhone 16 Pro Max | B6: https://www.mobilesentrix.ca/lcd-assembly-compatible-for-iphone-16-pro-max-aftermarket-aq7-incell-120hz | C6: 55.57 | D6: 100 | E6: =IFERROR((#REF! - C6) /#REF!, "") | F6: https://www.mobilesentrix.ca/oled-assembly-compatible-for-iphone-16-pro-max-aftermarket-pro-xo7-soft | G6: 175.19 | H6: 150 | I6: =IFERROR((#REF! - G6) /#REF!, "") | J6: 649 | K6: 149 | L6: 169 | M6: 159 | N6: 149 | O6: 50% Off | P6: 70% off
A7: iPhone 16 Pro | B7: https://www.mobilesentrix.ca/lcd-assembly-compatible-for-iphone-16-pro-aftermarket-aq7-incell-120hz | C7: 52.63 | D7: 100 | E7: =IFERROR((#REF! - C7) /#REF!, "") | F7: https://www.mobilesentrix.ca/oled-assembly-compatible-for-iphone-16-pro-aftermarket-pro-xo7-soft | G7: 130.89 | H7: 150 | I7: =IFERROR((#REF! - G7) /#REF!, "") | J7: 549 | K7: 149 | L7: 169 | M7: 159 | N7: 149 | O7: 50% Off | P7: 70% off
A8: iPhone 16 Plus | B8: https://www.mobilesentrix.ca/lcd-assembly-compatible-for-iphone-16-plus-aftermarket-aq7-incell | C8: 43.17 | D8: 100 | E8: =IFERROR((#REF! - C8) /#REF!, "") | F8: https://www.mobilesentrix.ca/oled-assembly-compatible-for-iphone-16-plus-aftermarket-pro-xo7-soft | G8: 81.07 | H8: 140 | I8: =IFERROR((#REF! - G8) /#REF!, "") | J8: 549 | K8: 139 | L8: 159 | M8: 159 | N8: 149 | O8: 50% Off | P8: 70% off
A9: iPhone 16 | B9: https://www.mobilesentrix.ca/lcd-assembly-compatible-for-iphone-16-aftermarket-aq7-incell | C9: 33.73 | D9: 100 | E9: =IFERROR((#REF! - C9) /#REF!, "") | F9: https://www.mobilesentrix.ca/oled-assembly-compatible-for-iphone-16-aftermarket-pro-xo7-soft | G9: 70.73 | H9: 140 | I9: =IFERROR((#REF! - G9) /#REF!, "") | J9: 449 | K9: 139 | L9: 159 | M9: 159 | N9: 149 | O9: 50% Off | P9: 70% off
A10: iPhone 16e | B10: https://www.mobilesentrix.ca/lcd-assembly-compatible-for-iphone-17e-16e-aftermarket-aq7-incell | C10: 30.47 | D10: 100 | E10: =IFERROR((#REF! - C10) /#REF!, "") | F10: https://www.mobilesentrix.ca/oled-assembly-compatible-for-iphone-17e-16e-aftermarket-pro-xo7-soft | G10: 70.34 | H10: 130 | I10: =IFERROR((#REF! - G10) /#REF!, "") | J10: 419 | K10: 139 | L10: 159 | M10: 159 | N10: 149 | O10: 50% Off | P10: 70% off
A11: iPhone 15 Pro Max | B11: https://www.mobilesentrix.ca/lcd-assembly-compatible-for-iphone-15-pro-max-aftermarket-aq7-incell-120hz | C11: 54.10 | D11: 100 | E11: =IFERROR((#REF! - C11) /#REF!, "") | F11: https://www.mobilesentrix.ca/oled-assembly-for-iphone-15-pro-max-aftermarket-pro-xo7-soft-120hz | G11: 68.71 | H11: 130 | I11: =IFERROR((#REF! - G11) /#REF!, "") | J11: 549 | K11: 129 | L11: 159 | M11: 149 | N11: 139 | O11: 50% Off | P11: 70% off
A12: iPhone 15 Pro | B12: https://www.mobilesentrix.ca/lcd-assembly-compatible-for-iphone-15-pro-aftermarket-aq7-incell-120hz | C12: 34.11 | D12: 100 | E12: =IFERROR((#REF! - C12) /#REF!, "") | F12: https://www.mobilesentrix.ca/oled-assembly-compatible-for-iphone-15-pro-aftermarket-pro-xo7-soft-120hz | G12: 69.30 | H12: 130 | I12: =IFERROR((#REF! - G12) /#REF!, "") | J12: 529 | K12: 129 | L12: 159 | M12: 149 | N12: 129 | O12: 50% Off | P12: 70% off
A13: iPhone 15 Plus | B13: https://www.mobilesentrix.ca/lcd-assembly-for-iphone-15-plus-aftermarket-aq7-incell | C13: 32.39 | D13: 100 | E13: =IFERROR((#REF! - C13) /#REF!, "") | F13: https://www.mobilesentrix.ca/oled-assembly-for-iphone-15-plus-aftermarket-pro-xo7-soft | G13: 86.19 | H13: 130 | I13: =IFERROR((#REF! - G13) /#REF!, "") | J13: 499 | K13: 129 | L13: 159 | M13: 139 | N13: 99 | O13: 50% Off | P13: 70% off
A14: iPhone 15 | B14: https://www.mobilesentrix.ca/lcd-assembly-for-iphone-15-aftermarket-aq7-incell | C14: 30.81 | D14: 70 | E14: =IFERROR((#REF! - C14) /#REF!, "") | F14: https://www.mobilesentrix.ca/oled-assembly-for-iphone-15-aftermarket-pro-xo7-soft | G14: 69.30 | H14: 120 | I14: =IFERROR((#REF! - G14) /#REF!, "") | J14: 469 | K14: 129 | L14: 159 | M14: 139 | N14: 99 | O14: 50% Off | P14: 70% off
A15: iPhone 14 Pro Max | B15: https://www.mobilesentrix.ca/lcd-assembly-compatible-for-iphone-14-pro-max-aftermarket-aq7-incell-120hz | C15: 51.43 | D15: 100 | E15: =IFERROR((#REF! - C15) /#REF!, "") | F15: https://www.mobilesentrix.ca/oled-assembly-for-iphone-14-pro-max-aftermarket-pro-xo7-soft | G15: 73.47 | H15: 120 | I15: =IFERROR((#REF! - G15) /#REF!, "") | J15: 499 | K15: 119 | L15: 149 | M15: 139 | N15: 99 | O15: 50% Off | P15: 70% off
A16: iPhone 14 Pro | B16: https://www.mobilesentrix.ca/lcd-assembly-compatible-for-iphone-14-pro-aftermarket-aq7-incell-120hz | C16: 36.97 | D16: 100 | E16: =IFERROR((#REF! - C16) /#REF!, "") | F16: https://www.mobilesentrix.ca/oled-assembly-compatible-for-iphone-14-pro-aftermarket-pro-xo7-soft-120hz | G16: 69.26 | H16: 120 | I16: =IFERROR((#REF! - G16) /#REF!, "") | J16: 449 | K16: 119 | L16: 149 | M16: 139 | N16: 99 | O16: 50% Off | P16: 70% off
A17: iPhone 14 Plus | B17: https://www.mobilesentrix.ca/lcd-assembly-for-iphone-14-plus-aftermarket-aq7-incell | C17: 33.20 | D17: 70 | E17: =IFERROR((#REF! - C17) /#REF!, "") | F17: https://www.mobilesentrix.ca/oled-assembly-for-iphone-14-plus-aftermarket-pro-xo7-soft | G17: 63.34 | H17: 120 | I17: =IFERROR((#REF! - G17) /#REF!, "") | J17: 449 | K17: 119 | L17: 149 | M17: 129 | N17: 99 | O17: 50% Off | P17: 70% off
A18: iPhone 14 | B18: https://www.mobilesentrix.ca/lcd-assembly-for-iphone-14-aftermarket-aq7-incell | C18: 26.86 | D18: 70 | E18: =IFERROR((#REF! - C18) /#REF!, "") | F18: https://www.mobilesentrix.ca/oled-assembly-for-iphone-14-aftermarket-pro-xo7-soft | G18: 67.39 | H18: 110 | I18: =IFERROR((#REF! - G18) /#REF!, "") | J18: 399 | K18: 119 | L18: 149 | M18: 129 | N18: 99 | O18: 50% Off | P18: 70% off
A19: iPhone 13 Pro Max | B19: https://www.mobilesentrix.ca/lcd-assembly-compatible-for-iphone-13-pro-max-aftermarket-aq7-incell-120hz | C19: 36.39 | D19: 70 | E19: =IFERROR((#REF! - C19) /#REF!, "") | F19: https://www.mobilesentrix.ca/oled-assembly-for-iphone-13-pro-max-aftermarket-pro-xo7-soft-120hz | G19: 63.34 | H19: 110 | I19: =IFERROR((#REF! - G19) /#REF!, "") | J19: NA | K19: 109 | L19: NA | M19: 129 | N19: 99 | O19: 50% Off | P19: 70% off
A20: iPhone 13 Pro | B20: https://www.mobilesentrix.ca/lcd-assembly-compatible-for-iphone-13-pro-aftermarket-aq7-incell-120hz | C20: 35.79 | D20: 70 | E20: =IFERROR((#REF! - C20) /#REF!, "") | F20: https://www.mobilesentrix.ca/oled-assembly-compatible-for-iphone-13-pro-aftermarket-pro-xo7-soft-120hz | G20: 74.77 | H20: 110 | I20: =IFERROR((#REF! - G20) /#REF!, "") | J20: NA | K20: 109 | L20: NA | M20: 129 | N20: 99 | O20: 50% Off | P20: 70% off
A21: iPhone 13 | B21: https://www.mobilesentrix.ca/lcd-assembly-for-iphone-13-aftermarket-aq7-incell | C21: 25.64 | D21: 70 | E21: =IFERROR((#REF! - C21) /#REF!, "") | F21: https://www.mobilesentrix.ca/oled-assembly-for-iphone-13-aftermarket-pro-xo7-soft | G21: 67.39 | H21: 110 | I21: =IFERROR((#REF! - G21) /#REF!, "") | J21: NA | K21: 109 | L21: NA | M21: 119 | N21: 99 | O21: 50% Off | P21: 70% off
A22: iPhone 13 Mini | B22: https://www.mobilesentrix.ca/lcd-assembly-for-iphone-13-mini-aftermarket-aq7-incell | C22: 38.01 | D22: 70 | E22: =IFERROR((#REF! - C22) /#REF!, "") | F22: https://www.mobilesentrix.ca/oled-assembly-for-iphone-13-mini-aftermarket-pro-xo7-soft | H22: 110 | I22: =IFERROR((#REF! - G22) /#REF!, "") | J22: NA | K22: 109 | L22: NA | M22: 119 | N22: 99 | O22: 50% Off | P22: 70% off
A23: iPhone 12 Pro Max | B23: https://www.mobilesentrix.ca/lcd-assembly-for-iphone-12-pro-max-aftermarket-incell | C23: 35.36 | D23: 70 | E23: =IFERROR((#REF! - C23) /#REF!, "") | F23: https://www.mobilesentrix.ca/oled-assembly-for-iphone-12-pro-max-aftermarket-pro-xo7-soft | G23: 68.87 | H23: 100 | I23: =IFERROR((#REF! - G23) /#REF!, "") | J23: NA | K23: 99 | L23: NA | M23: 119 | N23: 99 | O23: 50% Off | P23: 70% off
A24: iPhone 12 Pro | B24: https://www.mobilesentrix.ca/lcd-assembly-for-iphone-12-12-pro-aftermarket-incell | C24: 22.79 | D24: 70 | E24: =IFERROR((#REF! - C24) /#REF!, "") | F24: https://www.mobilesentrix.ca/oled-assembly-for-iphone-12-12-pro-aftermarket-pro-xo7-soft | G24: 60.01 | H24: 100 | I24: =IFERROR((#REF! - G24) /#REF!, "") | J24: NA | K24: 99 | L24: NA | M24: 119 | N24: 99 | O24: 50% Off | P24: 70% off
A25: iPhone 12 | B25: https://www.mobilesentrix.ca/lcd-assembly-for-iphone-12-12-pro-aftermarket-incell | C25: 22.79 | D25: 70 | E25: =IFERROR((#REF! - C25) /#REF!, "") | F25: https://www.mobilesentrix.ca/oled-assembly-for-iphone-12-12-pro-aftermarket-pro-xo7-soft | G25: 60.01 | H25: 90 | I25: =IFERROR((#REF! - G25) /#REF!, "") | J25: NA | K25: 89 | L25: NA | M25: 119 | N25: 99 | O25: 50% Off | P25: 70% off
A26: iPhone 12 Mini | B26: https://www.mobilesentrix.ca/lcd-assembly-compatible-for-iphone-12-mini-aftermarket-aq7-incell | C26: 37.11 | D26: 70 | E26: =IFERROR((#REF! - C26) /#REF!, "") | G26: Not Available | H26: 1 | I26: =IFERROR((#REF! - G26) /#REF!, "") | J26: NA | K26: 89 | L26: NA | M26: 119 | N26: 99 | O26: 50% Off | P26: 70% off
A27: iPhone 11 Pro Max | B27: https://www.mobilesentrix.ca/lcd-assembly-replacement-for-iphone-11-pro-max-aftermarket-aq7-incell | C27: 21.77 | D27: 70 | E27: =IFERROR((#REF! - C27) /#REF!, "") | F27: https://www.mobilesentrix.ca/oled-assembly-for-iphone-11-pro-max-aftermarket-pro-xo7-soft | G27: 57.50 | H27: 90 | I27: =IFERROR((#REF! - G27) /#REF!, "") | J27: NA | K27: 79 | L27: NA | M27: 119 | N27: 99 | O27: 50% Off | P27: 70% off
A28: iPhone 11 Pro | B28: https://www.mobilesentrix.ca/lcd-assembly-replacement-for-iphone-11-pro-aftermarket-aq7-incell | C28: 22.36 | D28: 70 | E28: =IFERROR((#REF! - C28) /#REF!, "") | F28: https://www.mobilesentrix.ca/oled-assembly-compatible-for-iphone-11-pro-aftermarket-plus-quality-boe-soft | G28: 63.11 | H28: 90 | I28: =IFERROR((#REF! - G28) /#REF!, "") | J28: NA | K28: 79 | L28: NA | M28: 119 | N28: 99 | O28: 50% Off | P28: 70% off
A29: iPhone 11 | B29: https://www.mobilesentrix.ca/lcd-assembly-with-steel-plate-pre-installed-replacement-for-iphone-11-aftermarket-aq7 | C29: 20.73 | D29: 70 | E29: =IFERROR((#REF! - C29) /#REF!, "") | F29: https://www.mobilesentrix.ca/lcd-assembly-compatible-for-iphone-11-aftermarket-plus-quality-xo7-cof-incell | G29: 25.37 | H29: 90 | I29: =IFERROR((#REF! - G29) /#REF!, "") | J29: NA | K29: 79 | L29: NA | M29: 99 | N29: 89 | O29: 50% Off | P29: 70% off
A30: iPhone XS Max | B30: https://www.mobilesentrix.ca/lcd-assembly-for-iphone-xs-max-aftermarket-pro-aq7-incell | C30: 21.10 | D30: 70 | E30: =IFERROR((#REF! - C30) /#REF!, "") | F30: https://www.mobilesentrix.ca/oled-assembly-for-iphone-xs-max-aftermarket-pro-xo7-soft | G30: 48.40 | H30: 90 | I30: =IFERROR((#REF! - G30) /#REF!, "") | J30: NA | K30: 79 | L30: NA | M30: 99 | N30: 89 | O30: 50% Off | P30: 70% off
A31: iPhone XS | B31: https://www.mobilesentrix.ca/lcd-assembly-replacement-for-iphone-xs-aftermarket-aq7-incell | C31: 22.94 | D31: 70 | E31: =IFERROR((#REF! - C31) /#REF!, "") | F31: https://www.mobilesentrix.ca/lcd-assembly-for-iphone-x-s-aftermarket-plus-quality | G31: 51.10 | H31: 80 | I31: =IFERROR((#REF! - G31) /#REF!, "") | J31: NA | K31: 79 | L31: NA | M31: 99 | N31: 89 | O31: 50% Off | P31: 70% off
A32: iPhone X | B32: https://www.mobilesentrix.ca/lcd-assembly-replacement-for-iphone-x-aftermarket-aq7-incell | C32: 22.94 | D32: 70 | E32: =IFERROR((#REF! - C32) /#REF!, "") | F32: https://www.mobilesentrix.ca/lcd-assembly-for-iphone-x-aftermarket-plus-quality | G32: 50.26 | H32: 80 | I32: =IFERROR((#REF! - G32) /#REF!, "") | J32: NA | K32: 79 | L32: NA | M32: 99 | N32: 89 | O32: 50% Off | P32: 70% off
A33: iPhone XR | B33: https://www.mobilesentrix.ca/lcd-assembly-with-steel-plate-pre-installed-replacement-for-iphone-xr-aftermarket-aq7 | C33: 20.53 | D33: 70 | E33: =IFERROR((#REF! - C33) /#REF!, "") | F33: https://www.mobilesentrix.ca/oled-assembly-compatible-for-iphone-xr-aftermarket-plus-quality-xo7-cof-incell | G33: 23.97 | H33: 80 | I33: =IFERROR((#REF! - G33) /#REF!, "") | J33: NA | K33: 79 | L33: NA | M33: 99 | N33: 89 | O33: 50% Off | P33: 70% off
A34: iPhone 8 Plus | B34: NA | E34: =IFERROR((#REF! - C34) /#REF!, "") | F34: https://www.mobilesentrix.ca/lcd-assembly-compatible-for-iphone-8-plus-aftermarket-plus-quality-xo7-incell-black | G34: 28.61 | H34: 80 | I34: =IFERROR((#REF! - G34) /#REF!, "") | K34: 69 | L34: NA | M34: 79 | N34: 79 | O34: 50% Off | P34: 70% off
A35: iPhone SE 20/22 | B35: NA | E35: =IFERROR((#REF! - C35) /#REF!, "") | F35: https://www.mobilesentrix.ca/lcd-assembly-compatible-for-iphone-8-aftermarket-plus-quality-xo7-black | G35: 19.89 | H35: 80 | I35: =IFERROR((#REF! - G35) /#REF!, "") | K35: 69 | L35: NA | M35: 79 | N35: 79 | O35: 50% Off | P35: 70% off
A36: iPhone 8 | B36: NA | E36: =IFERROR((#REF! - C36) /#REF!, "") | F36: https://www.mobilesentrix.ca/lcd-assembly-compatible-for-iphone-8-aftermarket-plus-quality-xo7-black | G36: 19.89 | H36: 80 | I36: =IFERROR((#REF! - G36) /#REF!, "") | K36: 69 | L36: NA | M36: 79 | N36: 79 | O36: 50% Off | P36: 70% off
A37: iPhone 7 Plus | B37: NA | E37: =IFERROR((#REF! - C37) /#REF!, "") | F37: https://www.mobilesentrix.ca/lcd-assembly-compatible-for-iphone-7-plus-aftermarket-plus-quality-xo7-incell-white | G37: 30.06 | H37: 80 | I37: =IFERROR((#REF! - G37) /#REF!, "") | J37: NA | K37: 69 | L37: NA | M37: 79 | N37: NA | O37: 50% Off | P37: 70% off
A38: iPhone 7 | B38: NA | E38: =IFERROR((#REF! - C38) /#REF!, "") | F38: https://www.mobilesentrix.ca/lcd-assembly-compatible-for-iphone-7-aftermarket-plus-quality-xo7-black | G38: 20.79 | H38: 80 | I38: =IFERROR((#REF! - G38) /#REF!, "") | J38: NA | K38: 69 | L38: NA | M38: 79 | N38: NA | O38: 50% Off | P38: 70% off
A39: iPhone 6s Plus | B39: NA | E39: =IFERROR((#REF! - C39) /#REF!, "") | F39: https://www.mobilesentrix.ca/lcd-assembly-compatible-for-iphone-6s-plus-aftermarket-plus-quality-xo7-incell-black | G39: 25.33 | H39: 80 | I39: =IFERROR((#REF! - G39) /#REF!, "") | J39: NA | K39: 59 | L39: NA | M39: NA | N39: NA | O39: 50% Off | P39: 70% off
A40: iPhone 6s | B40: https://www.mobilesentrix.ca/lcd-assembly-with-steel-plate-replacement-for-iphone-6s-aftermarket-aq7-black | C40: 18.70 | E40: =IFERROR((#REF! - C40) /#REF!, "") | F40: https://www.mobilesentrix.ca/lcd-assembly-compatible-for-iphone-6s-aftermarket-plus-quality-xo7-white | G40: 18.66 | H40: 80 | I40: =IFERROR((#REF! - G40) /#REF!, "") | J40: NA | K40: 59 | L40: NA | M40: NA | N40: NA | O40: 50% Off | P40: 70% off
...

Sheet Apple
A1: Model | B1: AQ7 MS | C1: AQ7 Labor | D1: AQ7 Margin | E1: AQ7 | F1: XO7 MS | G1: XO7 Labor | H1: XO7 Margin | I1: XO7 | J1: OEM Cost | K1: OEM Screen | L1: AM Battery | M1: Battery Cost | N1: OEM Battery | O1: Charge Port | P1: Back Glass Cost | Q1: Back Glass
A2: iPhone 17 Pro Max | B2: =RawData!C2 -> 77.73 | C2: 100 | D2: =IFERROR((E2-B2)/E2, "") -> 0.56575419 | E2: =ROUND($B2 + $C2, -1) - 1 -> 179 | F2: =RawData!G2 -> 204.73 | G2: 160 | H2: =IFERROR((I2-F2)/I2, "") -> 0.42972145 | I2: =ROUND(RawData!$G2 + RawData!$H2, -1) - 1 -> 359 | J2: 499 | K2: 659 | L2: NA | M2: 82 | N2: 179 | O2: 199 | P2: CHECK | Q2: 149
A3: iPhone 17 Pro | B3: =RawData!C3 -> 77.73 | C3: 100 | D3: =IFERROR((E3-B3)/E3, "") -> 0.56575419 | E3: =ROUND($B3 + $C3, -1) - 1 -> 179 | F3: =RawData!G3 -> 153.76 | G3: 160 | H3: =IFERROR((I3-F3)/I3, "") -> 0.50239482 | I3: =ROUND(RawData!$G3 + RawData!$H3, -1) - 1 -> 309 | J3: 429 | K3: 579 | L3: NA | M3: 82 | N3: 179 | O3: 199 | P3: CHECK | Q3: 149
A4: iPhone 17 | B4: =RawData!C4 -> 77.73 | C4: 100 | D4: =IFERROR((E4-B4)/E4, "") -> 0.56575419 | E4: =ROUND($B4 + $C4, -1) - 1 -> 179 | F4: =RawData!G4 -> 150.64 | G4: 150 | H4: =IFERROR((I4-F4)/I4, "") -> 0.49618729 | I4: =ROUND(RawData!$G4 + RawData!$H4, -1) - 1 -> 299 | J4: 429 | K4: 559 | L4: NA | M4: 82 | N4: 179 | O4: 199 | P4: CHECK | Q4: 149
A5: Iphone Air | B5: =RawData!C5 | C5: 110 | D5: =IFERROR((E5-B5)/E5, "") | E5: =ROUND($B5 + $C5, -1) - 1 -> #VALUE! | F5: =RawData!G5 -> 293.94 | G5: 150 | H5: =IFERROR((I5-F5)/I5, "") -> 0.3304328 | I5: =ROUND(RawData!$G5 + RawData!$H5, -1) - 1 -> 439 | K5: 569 | L5: NA | N5: 179 | O5: 199 | Q5: NA
A6: iPhone 16 Pro Max | B6: =RawData!C6 -> 55.57 | C6: 100 | D6: =IFERROR((E6-B6)/E6, "") -> 0.65050314 | E6: =ROUND($B6 + $C6, -1) - 1 -> 159 | F6: =RawData!G6 -> 175.19 | G6: 150 | H6: =IFERROR((I6-F6)/I6, "") -> 0.4675076 | I6: =ROUND(RawData!$G6 + RawData!$H6, -1) - 1 -> 329 | J6: 499 | K6: 649 | L6: 149 | M6: 28 | N6: 169 | O6: 159 | P6: 43 | Q6: 149
A7: iPhone 16 Pro | B7: =RawData!C7 -> 52.63 | C7: 100 | D7: =IFERROR((E7-B7)/E7, "") -> 0.64677852 | E7: =ROUND($B7 + $C7, -1) - 1 -> 149 | F7: =RawData!G7 -> 130.89 | G7: 150 | H7: =IFERROR((I7-F7)/I7, "") -> 0.53086022 | I7: =ROUND(RawData!$G7 + RawData!$H7, -1) - 1 -> 279 | J7: 407 | K7: 549 | L7: 149 | M7: 25 | N7: 169 | O7: 159 | P7: 43 | Q7: 149
A8: iPhone 16 Plus | B8: =RawData!C8 -> 43.17 | C8: 100 | D8: =IFERROR((E8-B8)/E8, "") -> 0.68942446 | E8: =ROUND($B8 + $C8, -1) - 1 -> 139 | F8: =RawData!G8 -> 81.07 | G8: 140 | H8: =IFERROR((I8-F8)/I8, "") -> 0.62981735 | I8: =ROUND(RawData!$G8 + RawData!$H8, -1) - 1 -> 219 | J8: 407 | K8: 549 | L8: 139 | M8: 25 | N8: 159 | O8: 159 | P8: 43 | Q8: 149
A9: iPhone 16 | B9: =RawData!C9 -> 33.73 | C9: 100 | D9: =IFERROR((E9-B9)/E9, "") -> 0.73852713 | E9: =ROUND($B9 + $C9, -1) - 1 -> 129 | F9: =RawData!G9 -> 70.73 | G9: 140 | H9: =IFERROR((I9-F9)/I9, "") -> 0.66157895 | I9: =ROUND(RawData!$G9 + RawData!$H9, -1) - 1 -> 209 | J9: 335 | K9: 449 | L9: 139 | M9: 22 | N9: 159 | O9: 159 | P9: 38 | Q9: 149
A10: iPhone 16e | B10: =RawData!C10 -> 30.47 | C10: 100 | D10: =IFERROR((E10-B10)/E10, "") -> 0.76379845 | E10: =ROUND($B10 + $C10, -1) - 1 -> 129 | F10: =RawData!G10 -> 70.34 | G10: 130 | H10: =IFERROR((I10-F10)/I10, "") -> 0.64653266 | I10: =ROUND(RawData!$G10 + RawData!$H10, -1) - 1 -> 199 | J10: 309 | K10: 419 | L10: 139 | M10: 25 | N10: 159 | O10: 159 | P10: NA | Q10: 149
A11: iPhone 15 Pro Max | B11: =RawData!C11 -> 54.10 | C11: 100 | D11: =IFERROR((E11-B11)/E11, "") -> 0.63691275 | E11: =ROUND($B11 + $C11, -1) - 1 -> 149 | F11: =RawData!G11 -> 68.71 | G11: 130 | H11: =IFERROR((I11-F11)/I11, "") -> 0.65472362 | I11: =ROUND(RawData!$G11 + RawData!$H11, -1) - 1 -> 199 | J11: 420 | K11: 549 | L11: 129 | M11: 28.56 | N11: 159 | O11: 149 | P11: 26 | Q11: 139
A12: iPhone 15 Pro | B12: =RawData!C12 -> 34.11 | C12: 100 | D12: =IFERROR((E12-B12)/E12, "") -> 0.7355814 | E12: =ROUND($B12 + $C12, -1) - 1 -> 129 | F12: =RawData!G12 -> 69.30 | G12: 130 | H12: =IFERROR((I12-F12)/I12, "") -> 0.65175879 | I12: =ROUND(RawData!$G12 + RawData!$H12, -1) - 1 -> 199 | J12: 373 | K12: 529 | L12: 129 | M12: 23.83 | N12: 159 | O12: 149 | P12: 27 | Q12: 129
A13: iPhone 15 Plus | B13: =RawData!C13 -> 32.39 | C13: 100 | D13: =IFERROR((E13-B13)/E13, "") -> 0.74891473 | E13: =ROUND($B13 + $C13, -1) - 1 -> 129 | F13: =RawData!G13 -> 86.19 | G13: 130 | H13: =IFERROR((I13-F13)/I13, "") -> 0.60643836 | I13: =ROUND(RawData!$G13 + RawData!$H13, -1) - 1 -> 219 | J13: 373 | K13: 499 | L13: 129 | M13: 22.99 | N13: 159 | O13: 139 | P13: 24 | Q13: 99
A14: iPhone 15 | B14: =RawData!C14 -> 30.81 | C14: 70 | D14: =IFERROR((E14-B14)/E14, "") -> 0.68878788 | E14: =ROUND($B14 + $C14, -1) - 1 -> 99 | F14: =RawData!G14 -> 69.30 | G14: 120 | H14: =IFERROR((I14-F14)/I14, "") -> 0.63333333 | I14: =ROUND(RawData!$G14 + RawData!$H14, -1) - 1 -> 189 | J14: 324 | K14: 469 | L14: 129 | M14: 20.68 | N14: 159 | O14: 139 | P14: 22 | Q14: 99
A15: iPhone 14 Pro Max | B15: =RawData!C15 -> 51.43 | C15: 100 | D15: =IFERROR((E15-B15)/E15, "") -> 0.65483221 | E15: =ROUND($B15 + $C15, -1) - 1 -> 149 | F15: =RawData!G15 -> 73.47 | G15: 120 | H15: =IFERROR((I15-F15)/I15, "") -> 0.61126984 | I15: =ROUND(RawData!$G15 + RawData!$H15, -1) - 1 -> 189 | J15: 430 | K15: 499 | L15: 119 | M15: 26.21 | N15: 149 | O15: 139 | P15: 17 | Q15: 99
A16: iPhone 14 Pro | B16: =RawData!C16 -> 36.97 | C16: 100 | D16: =IFERROR((E16-B16)/E16, "") -> 0.73402878 | E16: =ROUND($B16 + $C16, -1) - 1 -> 139 | F16: =RawData!G16 -> 69.26 | G16: 120 | H16: =IFERROR((I16-F16)/I16, "") -> 0.63354497 | I16: =ROUND(RawData!$G16 + RawData!$H16, -1) - 1 -> 189 | J16: 373 | K16: 449 | L16: 119 | M16: 23.76 | N16: 149 | O16: 139 | P16: 17 | Q16: 99
A17: iPhone 14 Plus | B17: =RawData!C17 -> 33.20 | C17: 70 | D17: =IFERROR((E17-B17)/E17, "") -> 0.66464646 | E17: =ROUND($B17 + $C17, -1) - 1 -> 99 | F17: =RawData!G17 -> 63.34 | G17: 120 | H17: =IFERROR((I17-F17)/I17, "") -> 0.64614525 | I17: =ROUND(RawData!$G17 + RawData!$H17, -1) - 1 -> 179 | J17: 373 | K17: 449 | L17: 119 | M17: 21.59 | N17: 149 | O17: 129 | P17: 17 | Q17: 99
A18: iPhone 14 | B18: =RawData!C18 -> 26.86 | C18: 70 | D18: =IFERROR((E18-B18)/E18, "") -> 0.72868687 | E18: =ROUND($B18 + $C18, -1) - 1 -> 99 | F18: =RawData!G18 -> 67.39 | G18: 110 | H18: =IFERROR((I18-F18)/I18, "") -> 0.62351955 | I18: =ROUND(RawData!$G18 + RawData!$H18, -1) - 1 -> 179 | J18: 324 | K18: 399 | L18: 119 | M18: 18.95 | N18: 149 | O18: 129 | P18: 17 | Q18: 99
A19: iPhone 13 Pro Max | B19: =RawData!C19 -> 36.39 | C19: 70 | D19: =IFERROR((E19-B19)/E19, "") -> 0.66614679 | E19: =ROUND($B19 + $C19, -1) - 1 -> 109 | F19: =RawData!G19 -> 63.34 | G19: 110 | H19: =IFERROR((I19-F19)/I19, "") -> 0.6252071 | I19: =ROUND(RawData!$G19 + RawData!$H19, -1) - 1 -> 169 | J19: NA | K19: NA | L19: 109 | M19: 25.23 | N19: NA | O19: 129 | P19: 15 | Q19: 99
A20: iPhone 13 Pro | B20: =RawData!C20 -> 35.79 | C20: 70 | D20: =IFERROR((E20-B20)/E20, "") -> 0.67165138 | E20: =ROUND($B20 + $C20, -1) - 1 -> 109 | F20: =RawData!G20 -> 74.77 | G20: 110 | H20: =IFERROR((I20-F20)/I20, "") -> 0.5822905 | I20: =ROUND(RawData!$G20 + RawData!$H20, -1) - 1 -> 179 | J20: NA | K20: NA | L20: 109 | M20: 19.45 | N20: NA | O20: 129 | P20: 15 | Q20: 99
A21: iPhone 13 | B21: =RawData!C21 -> 25.64 | C21: 70 | D21: =IFERROR((E21-B21)/E21, "") -> 0.7410101 | E21: =ROUND($B21 + $C21, -1) - 1 -> 99 | F21: =RawData!G21 -> 67.39 | G21: 110 | H21: =IFERROR((I21-F21)/I21, "") -> 0.62351955 | I21: =ROUND(RawData!$G21 + RawData!$H21, -1) - 1 -> 179 | J21: NA | K21: NA | L21: 109 | M21: 18.34 | N21: NA | O21: 119 | P21: 15 | Q21: 99
A22: iPhone 13 Mini | B22: =RawData!C22 -> 38.01 | C22: 70 | D22: =IFERROR((E22-B22)/E22, "") -> 0.6512844 | E22: =ROUND($B22 + $C22, -1) - 1 -> 109 | F22: =RawData!G22 | G22: 110 | H22: =IFERROR((I22-F22)/I22, "") | I22: =ROUND(RawData!$G22 + RawData!$H22, -1) - 1 -> #VALUE! | J22: NA | K22: NA | L22: 109 | M22: 14.52 | N22: NA | O22: 119 | P22: 12 | Q22: 99
A23: iPhone 12 Pro Max | B23: =RawData!C23 -> 35.36 | C23: 70 | D23: =IFERROR((E23-B23)/E23, "") -> 0.67559633 | E23: =ROUND($B23 + $C23, -1) - 1 -> 109 | F23: =RawData!G23 -> 68.87 | G23: 100 | H23: =IFERROR((I23-F23)/I23, "") -> 0.59248521 | I23: =ROUND(RawData!$G23 + RawData!$H23, -1) - 1 -> 169 | J23: NA | K23: NA | L23: 99 | M23: 23.45 | N23: NA | O23: 119 | P23: 14 | Q23: 99
A24: iPhone 12 Pro | B24: =RawData!C24 -> 22.79 | C24: 70 | D24: =IFERROR((E24-B24)/E24, "") -> 0.74393258 | E24: =ROUND($B24 + $C24, -1) - 1 -> 89 | F24: =RawData!G24 -> 60.01 | G24: 100 | H24: =IFERROR((I24-F24)/I24, "") -> 0.62257862 | I24: =ROUND(RawData!$G24 + RawData!$H24, -1) - 1 -> 159 | J24: NA | K24: NA | L24: 99 | M24: 15.76 | N24: NA | O24: 119 | P24: 14 | Q24: 99
A25: iPhone 12 | B25: =RawData!C25 -> 22.79 | C25: 70 | D25: =IFERROR((E25-B25)/E25, "") -> 0.74393258 | E25: =ROUND($B25 + $C25, -1) - 1 -> 89 | F25: =RawData!G25 -> 60.01 | G25: 90 | H25: =IFERROR((I25-F25)/I25, "") -> 0.59724832 | I25: =ROUND(RawData!$G25 + RawData!$H25, -1) - 1 -> 149 | J25: NA | K25: NA | L25: 89 | M25: 15.76 | N25: NA | O25: 119 | P25: 8 | Q25: 99
A26: iPhone 12 Mini | B26: =RawData!C26 -> 37.11 | C26: 70 | D26: =IFERROR((E26-B26)/E26, "") -> 0.65954128 | E26: =ROUND($B26 + $C26, -1) - 1 -> 109 | F26: =RawData!G26 -> Not Available | G26: 1 | H26: =IFERROR((I26-F26)/I26, "") | I26: =ROUND(RawData!$G26 + RawData!$H26, -1) - 1 -> #VALUE! | J26: NA | K26: NA | L26: 89 | M26: 15.24 | N26: NA | O26: 119 | P26: 15 | Q26: 99
A27: iPhone 11 Pro Max | B27: =RawData!C27 -> 21.77 | C27: 70 | D27: =IFERROR((E27-B27)/E27, "") -> 0.75539326 | E27: =ROUND($B27 + $C27, -1) - 1 -> 89 | F27: =RawData!G27 -> 57.50 | G27: 90 | H27: =IFERROR((I27-F27)/I27, "") -> 0.61409396 | I27: =ROUND(RawData!$G27 + RawData!$H27, -1) - 1 -> 149 | J27: NA | K27: NA | L27: 79 | M27: 19.94 | N27: NA | O27: 119 | P27: 11 | Q27: 99
A28: iPhone 11 Pro | B28: =RawData!C28 -> 22.36 | C28: 70 | D28: =IFERROR((E28-B28)/E28, "") -> 0.74876404 | E28: =ROUND($B28 + $C28, -1) - 1 -> 89 | F28: =RawData!G28 -> 63.11 | G28: 90 | H28: =IFERROR((I28-F28)/I28, "") -> 0.57644295 | I28: =ROUND(RawData!$G28 + RawData!$H28, -1) - 1 -> 149 | J28: NA | K28: NA | L28: 79 | M28: 27.88 | N28: NA | O28: 119 | P28: 10 | Q28: 99
A29: iPhone 11 | B29: =RawData!C29 -> 20.73 | C29: 70 | D29: =IFERROR((E29-B29)/E29, "") -> 0.76707865 | E29: =ROUND($B29 + $C29, -1) - 1 -> 89 | F29: =RawData!G29 -> 25.37 | G29: 90 | H29: =IFERROR((I29-F29)/I29, "") -> 0.78680672 | I29: =ROUND(RawData!$G29 + RawData!$H29, -1) - 1 -> 119 | J29: NA | K29: NA | L29: 79 | M29: 23.65 | N29: NA | O29: 99 | P29: 7 | Q29: 89
A30: iPhone XS Max | B30: =RawData!C30 -> 21.10 | C30: 70 | D30: =IFERROR((E30-B30)/E30, "") -> 0.76292135 | E30: =ROUND($B30 + $C30, -1) - 1 -> 89 | F30: =RawData!G30 -> 48.40 | G30: 90 | H30: =IFERROR((I30-F30)/I30, "") -> 0.65179856 | I30: =ROUND(RawData!$G30 + RawData!$H30, -1) - 1 -> 139 | J30: NA | K30: NA | L30: 79 | M30: 20.64 | N30: NA | O30: 99 | P30: 10 | Q30: 89
... A33: iPhone XR | B33: =RawData!C33 -> 20.53 | C33: 70 | D33: =IFERROR((E33-B33)/E33, "") -> 0.76932584 | E33: =ROUND($B33 + $C33, -1) - 1 -> 89 | F33: =RawData!G33 -> 23.97 | G33: 80 | H33: =IFERROR((I33-F33)/I33, "") -> 0.75787879 | I33: =ROUND(RawData!$G33 + RawData!$H33, -1) - 1 -> 99 | J33: NA | K33: NA | L33: 79 | M33: 19.31 | N33: NA | O33: 99 | P33: 10 | Q33: 89
A34: iPhone 8 Plus | B34: =RawData!C34 | D34: =IFERROR((E34-B34)/E34, "") | E34: =ROUND($B34 + $C34, -1) - 1 -> #VALUE! | F34: =RawData!G34 -> 28.61 | G34: 80 | H34: =IFERROR((I34-F34)/I34, "") -> 0.73752294 | I34: =ROUND(RawData!$G34 + RawData!$H34, -1) - 1 -> 109 | J34: NA | K34: NA | L34: 69 | M34: 15.36 | N34: NA | O34: 79 | P34: 10 | Q34: 79
A35: iPhone SE 20/22 | B35: =RawData!C35 | D35: =IFERROR((E35-B35)/E35, "") | E35: =ROUND($B35 + $C35, -1) - 1 -> #VALUE! | F35: =RawData!G35 -> 19.89 | G35: 80 | H35: =IFERROR((I35-F35)/I35, "") -> 0.79909091 | I35: =ROUND(RawData!$G35 + RawData!$H35, -1) - 1 -> 99 | J35: NA | K35: NA | L35: 69 | M35: 14.95 | N35: NA | O35: 79 | P35: 10 | Q35: 79
A36: iPhone 8 | B36: =RawData!C36 | D36: =IFERROR((E36-B36)/E36, "") | E36: =ROUND($B36 + $C36, -1) - 1 -> #VALUE! | F36: =RawData!G36 -> 19.89 | G36: 80 | H36: =IFERROR((I36-F36)/I36, "") -> 0.79909091 | I36: =ROUND(RawData!$G36 + RawData!$H36, -1) - 1 -> 99 | J36: NA | K36: NA | L36: 69 | M36: 13.12 | N36: NA | O36: 79 | P36: 10 | Q36: 79
A37: iPhone 7 Plus | B37: =RawData!C37 | D37: =IFERROR((E37-B37)/E37, "") | E37: =ROUND($B37 + $C37, -1) - 1 -> #VALUE! | F37: =RawData!G37 -> 30.06 | G37: 80 | H37: =IFERROR((I37-F37)/I37, "") -> 0.72422018 | I37: =ROUND(RawData!$G37 + RawData!$H37, -1) - 1 -> 109 | J37: NA | K37: NA | L37: 69 | M37: 13.21 | N37: NA | O37: 79 | P37: NA | Q37: NA
A38: iPhone 7 | B38: =RawData!C38 | D38: =IFERROR((E38-B38)/E38, "") | E38: =ROUND($B38 + $C38, -1) - 1 -> #VALUE! | F38: =RawData!G38 -> 20.79 | G38: 80 | H38: =IFERROR((I38-F38)/I38, "") -> 0.79 | I38: =ROUND(RawData!$G38 + RawData!$H38, -1) - 1 -> 99 | J38: NA | K38: NA | L38: 69 | M38: 11.42 | N38: NA | O38: 79 | P38: NA | Q38: NA
A39: iPhone 6s Plus | B39: =RawData!C39 | D39: =IFERROR((E39-B39)/E39, "") | E39: =ROUND($B39 + $C39, -1) - 1 -> #VALUE! | F39: =RawData!G39 -> 25.33 | G39: 80 | H39: =IFERROR((I39-F39)/I39, "") -> 0.76761468 | I39: =ROUND(RawData!$G39 + RawData!$H39, -1) - 1 -> 109 | K39: NA | L39: 59 | N39: NA | O39: NA | Q39: NA
A40: iPhone 6s | B40: =RawData!C40 -> 18.70 | D40: =IFERROR((E40-B40)/E40, "") -> 0.015789474 | E40: =ROUND($B40 + $C40, -1) - 1 -> 19 | F40: =RawData!G40 -> 18.66 | G40: 80 | H40: =IFERROR((I40-F40)/I40, "") -> 0.81151515 | I40: =ROUND(RawData!$G40 + RawData!$H40, -1) - 1 -> 99 | K40: NA | L40: 59 | N40: NA | O40: NA | Q40: NA
A41: iPhone 6 Plus | B41: =RawData!C41 | D41: =IFERROR((E41-B41)/E41, "") | E41: =ROUND($B41 + $C41, -1) - 1 -> #VALUE! | F41: =RawData!G41 -> 24.16 | G41: 80 | H41: =IFERROR((I41-F41)/I41, "") -> 0.7559596 | I41: =ROUND(RawData!$G41 + RawData!$H41, -1) - 1 -> 99 | K41: NA | L41: 59 | N41: NA | O41: NA | Q41: NA
A42: iPhone 6 | B42: =RawData!C42 | D42: =IFERROR((E42-B42)/E42, "") | E42: =ROUND($B42 + $C42, -1) - 1 -> #VALUE! | F42: =RawData!G42 -> 18.99 | G42: 80 | H42: =IFERROR((I42-F42)/I42, "") -> 0.80818182 | I42: =ROUND(RawData!$G42 + RawData!$H42, -1) - 1 -> 99 | K42: NA | L42: 59 | N42: NA | O42: NA | Q42: NA

Sheet Samsung
A1: Galaxy 'S' Series | B1: OLED | C1: OCTA | D1: Charge Port | E1: Battery | F1: Back Glass
A2: S26 Ultra | B2: 349 | C2: 449 | D2: 119 | E2: 129 | F2: 129
A3: S26+ | B3: 269 | D3: 119 | E3: 129 | F3: 129
A4: S26 | B4: 249 | D4: 119 | E4: 129 | F4: 129
A5: S25 Ultra | B5: 349 | C5: 449 | D5: 119 | E5: 129 | F5: 129
A6: S25+ | B6: 269 | D6: 119 | E6: 129 | F6: 129
A7: S25 | B7: 249 | D7: 119 | E7: 129 | F7: 129
A8: S24 Ultra | B8: 349 | C8: 439 | D8: 119 | E8: 119 | F8: 119
A9: S24+ | B9: 279 | D9: 119 | E9: 119 | F9: 119
A10: S24 | B10: 249 | D10: 119 | E10: 119 | F10: 119
A11: S24 FE | B11: 229 | D11: 119 | E11: 119 | F11: 119
A12: S23 Ultra | B12: 349 | C12: 439 | D12: 119 | E12: 109 | F12: 119
A13: S23+ | B13: 299 | D13: 119 | E13: 109 | F13: 119
A14: S23 | B14: 249 | D14: 119 | E14: 109 | F14: 119
A15: S23 FE | B15: 229 | D15: 119 | E15: 109 | F15: 119
A16: S22 Ultra | B16: 339 | C16: 389 | D16: 99 | E16: 99 | F16: 109
A17: S22+ | B17: 229 | D17: 99 | E17: 99 | F17: 109
A18: S22 | B18: 199 | D18: 99 | E18: 99 | F18: 109
A19: S21 Ultra | B19: 289 | C19: 339 | D19: 99 | E19: 89 | F19: 99
A20: S21+ | B20: 229 | D20: 99 | E20: 89 | F20: 99
A21: S21 FE | B21: 229 | D21: 99 | E21: 89 | F21: 99
A22: S21 | B22: 229 | D22: 99 | E22: 89 | F22: 99
A23: S20 Ultra | B23: 269 | C23: 339 | D23: 89 | E23: 79 | F23: 89
A24: S20 + | B24: 229 | D24: 89 | E24: 79 | F24: 89
A25: S20 FE | B25: 229 | D25: 89 | E25: 79 | F25: 89
A26: A Series | B26: Screen
A27: A54 | B27: 249
A28: A53 | B28: 229
A29: A52 | B29: 209
A30: A32 | B30: 179
A31: A71 | B31: 229
A32: A51 | B32: 209
A33: A70 | B33: 179
A34: A50 | B34: 179
A35: A36 | B35: 229
A36: A35 | B36: 199
A37: A23 | B37: 179
A38: A21 | B38: 169
... A47: A03s | B47: 139
A48: Galaxy 'Z' Series | B48: OLED | C48: OCTA | D48: Sub UB
...

Sheet Google 
A1: Model | B1: OEM Screen | C1: Battery
A2: Pixel 10 Pro Fold | B2: $1099 innie / $289 outie | C2: 249
A3: Pixel 10 Pro XL | B3: 419 | C3: 179
A4: Pixel 10 Pro | B4: 389 | C4: 169
A5: Pixel 10 | B5: 309 | C5: 169
A6: Pixel 9a | B6: 239 | C6: 139
A7: Pixel 9 Pro Fold | B7: $999 innie / $239 outie | C7: 249
A8: Pixel 9 Pro XL | B8: 399 | C8: 179
A9: Pixel 9 Pro | B9: 279 | C9: 169
A10: Pixel 9 | B10: 279 | C10: 159
A11: Pixel 8 Pro | B11: 379 | C11: 139
A12: Pixel 8 | B12: 279 | C12: 129
A13: Pixel 8A | B13: 199 | C13: 119
A14: Pixel 7 Pro | B14: 339 | C14: 129
A15: Pixel 7 | B15: 229 | C15: 119
A16: Pixel 7A | B16: 199 | C16: 109
A17: Pixel 6 Pro | B17: 349 | C17: 129
A18: Pixel 6 | B18: 209 | C18: 119
A19: Pixel 6A | B19: 199 | C19: 99
